Workbook
Name BondModes: #REF!
Name BondModes: #REF!
Name BondModes: #REF!
Name BondModes: #REF!
Name BondModes: #REF!
Name BondModes: #REF!
Name BondModes: #REF!
Name BondModes: #REF!
Name BondModes: #REF!
Name BondModes: #REF!
Name BondModes: #REF!
Name Erasure_Coding: [1]!Table_19[Erasure_Coding]
Name Erasure_Coding: Table_19[Erasure_Coding]
Name Erasure_Coding: Table_19[Erasure_Coding]
Name Fault_Tolerance: [1]!Table_7[Method]
Name Fault_Tolerance: Table_7[Method]
Name Fault_Tolerance: Table_7[Method]
Name Hybrid: Firewalls!$A$521
Name Nodes: [1]Model_DB!$B$3:$B$11
Name Nodes: Model_DB!$B$2:$B$56
Name PortType: #REF!
Name PortType: #REF!
Name PortType: #REF!
Name PortType: #REF!
Name PortType: #REF!
Name PortType: #REF!
Name PortType: #REF!
Name PortType: #REF!
Name PortType: #REF!
Name PortType: #REF!
Name PortType: #REF!
Name Replication_Factor: [1]!Table_8[Replication_Factor]
Name Replication_Factor: Table_8[Replication_Factor]
Name Replication_Factor: Table_8[Replication_Factor]
Name Uplinks: #REF!
Name Uplinks: #REF!
Name Uplinks: #REF!
Name Uplinks: #REF!
Name Uplinks: #REF!
Name Uplinks: #REF!
Name Uplinks: #REF!
Name Uplinks: #REF!
Name Uplinks: #REF!
Name Uplinks: #REF!
Name Uplinks: #REF!
Name YesNo: #REF!
Name YesNo: #REF!
Name YesNo: #REF!
Name YesNo: #REF!
Name YesNo: #REF!
Name YesNo: #REF!
Name YesNo: #REF!
Name YesNo: #REF!
Name YesNo: #REF!
Name YesNo: #REF!
Name YesNo: #REF!

Sheet Cover Page
A1: Complete both the Cover Page and PreInstall Checklist tabs, then return this workbook to your Project Coordinator.
D2: PreInstallation Checklist
B3: Complete the yellow highlighted sections on this tab and PreInstall Checklist, then return this workbook to your Project Coordinator.
B4: Note: Your installation WILL NOT be scheduled until this tab and PreInstall_Checklist are completed and returned.
B6: Note: The tabs to collect information for Cloud and Virtual Editions are hidden by default, as are some tabs that include explanatory information helpful for filling out the spreadsheet. To reveal these tabs, open the workbook in Excel, right-click on any tab, and select Unhide.
A8: 1. Contact Information
A9: a. | B9: Company Name:
A10: b. | B10: Install Address:
A11: c. | B11: Customer Contact 1: | C11: Name, Role | D11: Email, Phone
A12: d. | B12: Customer Contact 2: | C12: Name, Role | D12: Email, Phone
A13: e. | B13: Cohesity Account Representative: | C13: Name | D13: Email, Phone
A14: f. | B14: Cohesity Sales Engineer: | C14: Name | D14: Email, Phone
A15: g. | B15: Cohesity Coordinator: | C15: Name | D15: Email, Phone
A17: 2. Reference Information | C17: Go to https://my.cohesity.com/s/ for User Account Creation and Reference Information
A18: a. | B18: User Account Creation and Access | C18: Go to: https://my.cohesity.com/s/login/SelfRegister
A19: b. | B19: Firewall Ports | C19: See Manage Firewall Ports in Cohesity Documentation
A20: c. | B20: Cabling | C20: See Initial Cluster Setup for hardware model purchased.
A21: d. | B21: DNS Config | C21: See Configure Settings for more information.
A22: e. | B22: NTP | C22: See Initial Cluster Setup for hardware model purchased.
A23: f. | B23: Security Hardening Best Practices | C23: Cohesity Platform Security Hardening Best Practices Guide | D23: IMPORTANT: Requirements for Security Hardening activities indicated by 'blue-box' require customer preparedness in-advance to implement features at time of installation.
B25: Legend - Cell Color Meaning
B26: Customer Input - REQUIRED
B27: Calculation - DO NOT CHANGE
B28: Important or Warning
B29: Security Hardening Requirements
B30: Crucial Notification!!!

Sheet PreInstall_Checklist
A1: Required Information | C1: Response | D1: Notes
A3: 1. Site Readiness
A4: a. | B4: Installation Type? | D4: * For Virtual Edition & Cloud Edition, see Unhide tabs 2 and 3
A5: b. | B5: Rack Grid # and RU # where hardware is to be installed? (Cohesity HW On-site ONLY) | D5: Customer is responsible for racking and cabling of 3rd party hardware
A6: c. | B6: Have power capacity requirements been met? | D6: For power consumption guidance, see 3.b thru 3.e
A7: d. | B7: Are there (2) PDUs in the rack?
A8: e. | B8: Is the rack/cabinet depth sufficient for the hardware being installed?
A9: f. | B9: Is there adequate access space in front and behind racks/cabinets?
A10: g. | B10: Have networking cables been pulled to the rack and labeled?
A11: h. | B11: Is there adequate space in rack/cabinet for addtioanl cables?
A12: i. | B12: De we have solution sizing information from the SE? | D12: For Version #, Storage Domain, Fault Tolerance, Replication Factor settings, per SE design.
A13: j. | B13: Do you have a KVM and is it available for us to use? (Cohesity HW On-site ONLY)
A14: k. | B14: Is there access to a server lift? (Cohesity HW On-site ONLY)
A15: l. | B15: Did you purchase your nodes through a Cohesity reseller?
A16: m. | B16: Have you changed any hardware configuration on the nodes, such as NICs? | D16: Describe any changes you have made to the hardware configuration.
A17: n. | B17: Anything else we should be aware of regarding this DC and installation space?
A18: 2. Hardware Information
A19: a. | B19: Hardware Model?
A20: b. | B20: # of Nodes?
A21: c. | B21: Data Network Connection Type?
A22: d. | B22: NIC or SFP type?
A23: e. | B23: How many port connections should be used for this hardware installation?
A24: f. | B24: Switch Model we are connecting to? | D24: WARNING: Use of FEX Switches with Cohesity may result in performance degradation. Contact your Sales Engineer for more information.
A25: g. | B25: # of Blocks | C25: =IF(OR(C19="C2000 Series",C19="C4000 Series",C19="C5000 Series",C19="C5200 Series",C19="Dell PowerEdge C6420", C19="CX8000 Series", C19="HPE Apollo r2200"),ROUNDUP(C20/4,0),C20) -> 0
A26: h. | B26: Rack Units (RU) Per Node or Block | C26: =IF(C19="C2000 Series",Model_DB!D2,IF(C19="C3500 Series",Model_DB!D3,IF(C19="C4000 Series",Model_DB!D4,IF(C19="C5000 Series",Model_DB!D5,IF(C19="C5200 Series",Model_DB!D6,IF(C19="C6000 Series",Model_DB!D7,IF(C19="Cisco UCS C220 M5",Model_DB!D8,IF(C19="Cisco UCS 220 M5 All Flash",Model_DB!D9,IF(C19="Cisco UCS C220 M6",Model_DB!D10,IF(C19="Cisco UCS C220 M6 All Flash",Model_DB!D11,IF(C19="Cisco UCS C220 M7 All-Flash",Model_DB!D12,IF(C19="Cisco UCS C220 M6 ROBO",Model_DB!D13,IF(C19="Cisco UCS C225 M8 All-Flash",Model_DB!D14,IF(C19="Cisco UCS C240 M4",Model_DB!D15,IF(C19="Cisco UCS C240 M5",Model_DB!D16,IF(C19="Cisco UCS C240 M6",Model_DB!D17,IF(C19="Cisco UCS C240 M6 All-Flash",Model_DB!D18,IF(C19="Cisco C240 M6 ROBO",Model_DB!D19,IF(C19="Cisco UCS S3260",Model_DB!D20,IF(C19="Cisco UCS X210c M6",Model_DB!D21,IF(C19="CX8000 Series",Model_DB!D22,IF(C19="Dell PowerEdge C6420",Model_DB!D23,IF(C19="Dell PowerEdge R640",Model_DB!D24, IF(C19="Dell PowerEdge R650",Model_DB!D25,IF(C19="Dell PowerEdge R660",Model_DB!D26,IF(C19="Dell PowerEdge R6625",Model_DB!D27,IF(C19="Dell PowerEdge R740xd",Model_DB!D28,IF(C19="Dell PowerEdge R750",Model_DB!D29,IF(C19="Dell PowerEdge R7615",Model_DB!D30,IF(C19="Dell PowerEdge R760",Model_DB!D31,IF(C19="Fujitsu Primergy RX2540 M5",Model_DB!D32,IF(C19="Fujitsu RX2540 M6",Model_DB!D33,IF(C19="Fujitsu RX2540 M7",Model_DB!D34,IF(C19="HPE Alletra Storage Server 4120",Model_DB!D35,IF(C19="HPE Apollo 4200 Gen10",Model_DB!D36,IF(C19="HPE Apollo 4510 Gen10",Model_DB!D37,IF(C19="HPE Apollo r2200",Model_DB!D38,IF(C19="HPE DL320 Gen11",Model_DB!D39,IF(C19="HPE DL325 G11 All Flash",Model_DB!D40,IF(C19="HPE ProLiant DL325 Gen11",Model_DB!D41,IF(C19="HPE ProLiant DL325 Gen11",Model_DB!D41,IF(C19="HPE ProLiant DL345 Gen11",Model_DB!D42,IF(C19="HPE ProLiant DL360 Gen10",Model_DB!D43,IF(C19="HPE ProLiant DL360 Gen10 Plus All-Flash",Model_DB!D44,IF(C19="HPE ProLiant DL380 Gen10",Model_DB!D45,IF(C19="HPE ProLiant DL380 Gen10 Plus",Model_DB!D46,IF(C19="HPE Proliant DL380 Gen11",Model_DB!D47,IF(C19="Intel M50FCP 2U R208 Platform",Model_DB!D48,IF(C19="Intel R1208WF All-Flash",Model_DB!D49,IF(C19="Intel R2208WF All-Flash",Model_DB!D50,IF(C19="Lenovo ThinkSystem SR645 All Flash",Model_DB!D51,IF(C19="Lenovo SR645 ROBO",Model_DB!D52,IF(C19="Lenovo SR650",Model_DB!D53,IF(C19="Lenovo ThinkSystem SR665 v3 All-Flash",Model_DB!D54,IF(C19="SuperMicro 6029-E1CR12L",Model_DB!D55,IF(C19="SuperMicro 1029U-TN12RV",Model_DB!D56)))))))))))))))))))))))))))))))))))))))))))))))))))))))) -> FALSE
A27: i. | B27: Requested Cohesity OS Version (If Any)? | D27: * Will install latest upgradeable LTS version unless SE Design specifies.
A28: 3. Physical Connection Requirements | C28: (Cells highlighted in pink are auto-populated based on values entered above - DO NOT CHANGE)
A29: a. | B29: Rack Space (RU) | C29: =CONCATENATE(C25*C26, "U") -> 0U | D29: If installing C5000s into a 110V environment, only 2 nodes per chassis is supported. Therefore double the stated RU requirements.
A30: b. | B30: Power Cables Needed (# of blocks * # of outlets on PDU) | C30: =IF(C19="C2000 Series",(C25*Model_DB!F2),IF(C19="C3500 Series",(C25*Model_DB!F3),IF(C19="C4000 Series",(C25*Model_DB!F4),IF(C19="C5000 Series",(C25*Model_DB!F5),IF(C19="C5200 Series",(C25*Model_DB!F6),IF(C19="C6000 Series",(C25*Model_DB!F7),IF(C19="Cisco UCS C220 M5",(C25*Model_DB!F8),IF(C19="Cisco UCS 220 M5 All Flash",(C25*Model_DB!F9),IF(C19="Cisco UCS C220 M6",(C25*Model_DB!F10),IF(C19="Cisco UCS C220 M6 All Flash",(C25*Model_DB!F11),IF(C19="Cisco UCS C220 M7 All-Flash",(C25*Model_DB!F12),IF(C19="Cisco UCS C220 M6 ROBO",(C25*Model_DB!F13),IF(C19="Cisco UCS C225 M8 All-Flash",(C25*Model_DB!F14),IF(C19="Cisco UCS C240 M4",(C25*Model_DB!F15),IF(C19="Cisco UCS C240 M5",(C25*Model_DB!F16),IF(C19="Cisco UCS C240 M6",(C25*Model_DB!F17),IF(C19="Cisco UCS C240 M6 All-Flash",(C25*Model_DB!F18),IF(C19="Cisco C240 M6 ROBO",(C25*Model_DB!F19),IF(C19="Cisco UCS S3260",(C25*Model_DB!F20),IF(C19="Cisco UCS X210c M6",(C25*Model_DB!F21),IF(C19="CX8000 Series",(C25*Model_DB!F22),IF(C19="Dell PowerEdge C6420",(C25*Model_DB!F23),IF(C19="Dell PowerEdge R640",(C25*Model_DB!F24),IF(C19="Dell PowerEdge R650",(C25*Model_DB!F25),IF(C19="Dell PowerEdge R660",(C25*Model_DB!F26),IF(C19="Dell PowerEdge R6625",(C25*Model_DB!F27),IF(C19="Dell PowerEdge R740xd",(C25*Model_DB!F28),IF(C19="Dell PowerEdge R750",(C25*Model_DB!F29),IF(C19="Dell PowerEdge R7615",(C25*Model_DB!F30),IF(C19="Dell PowerEdge R760",(C25*Model_DB!F31),IF(C19="Fujitsu Primergy RX2540 M5",(C25*Model_DB!F32),IF(C19="Fujitsu RX2540 M6",(C25*Model_DB!F33),IF(C19="Fujitsu RX2540 M7",(C25*Model_DB!F34),IF(C19="HPE Alletra Storage Server 4120",(C25*Model_DB!F35),IF(C19="HPE Apollo 4200 Gen10",(C25*Model_DB!F36),IF(C19="HPE DL320 Gen11",(C25*Model_DB!F37),IF(C19="HPE DL325 G11 All Flash",(C25*Model_DB!F38),IF(C19="HPE Apollo 4510 Gen10",(C25*Model_DB!F39),IF(C19="HPE Apollo r2200",(C25*Model_DB!F40),IF(C19="HPE ProLiant DL325 Gen11",(C25*Model_DB!F41),IF(C19="HPE ProLiant DL345 Gen11",(C25*Model_DB!F42),IF(C19="HPE ProLiant DL360 Gen10",(C25*Model_DB!F43),IF(C19="HPE ProLiant DL360 Gen10 Plus All-Flash",(C25*Model_DB!F44),IF(C19="HPE ProLiant DL380 Gen10",(C25*Model_DB!F45),IF(C19="HPE ProLiant DL380 Gen10 Plus",(C25*Model_DB!F46),IF(C19="HPE Proliant DL380 Gen11",(C25*Model_DB!F47),IF(C19="Intel M50FCP 2U R208 Platform",(C25*Model_DB!F48),IF(C19="Intel R1208WF All-Flash",(C25*Model_DB!F49),IF(C19="Intel R2208WF All-Flash",(C25*Model_DB!F50),IF(C19="Lenovo ThinkSystem SR645 All Flash",(C25*Model_DB!F51),IF(C19="Lenovo SR645 ROBO",(C25*Model_DB!F52),IF(C19="Lenovo SR650",(C25*Model_DB!F53),IF(C19="Lenovo ThinkSystem SR665 v3 All-Flash",(C25*Model_DB!F54),IF(C19="SuperMicro 6029-E1CR12L",(C25*Model_DB!F55),IF(C19="SuperMicro 1029U-TN12RV",(C25*Model_DB!F56)))))))))))))))))))))))))))))))))))))))))))))))))))))))) -> FALSE | D30: * Cohesity C5K, C6K nodes ship with C13-C14 cables, CX8K nodes ship with C19-C20 cables. CX8K nodes only support 220v to 240v. | G30: The Images below are for representation purposes only. Port layout and appearance will vary depending on the hardware model.
A31: c. | B31: Peak Power Required (Watts) | C31: =IF(C19="C2000 Series",(C20*Model_DB!E2),IF(C19="C3500 Series",(C20*Model_DB!E3),IF(C19="C4000 Series",(C20*Model_DB!E4),IF(C19="C5000 Series",(C20*Model_DB!E5),IF(C19="C5200 Series",(C20*Model_DB!E6),IF(C19="C6000 Series",(C20*Model_DB!E7),IF(C19="Cisco UCS C220 M5",(C20*Model_DB!E8),IF(C19="Cisco UCS 220 M5 All Flash",(C20*Model_DB!E9),IF(C19="Cisco UCS C220 M6",(C20*Model_DB!E10),IF(C19="Cisco UCS C220 M6 All Flash",(C20*Model_DB!E11),IF(C19="Cisco UCS C220 M7 All-Flash",(C20*Model_DB!E12),IF(C19="Cisco UCS C220 M6 ROBO",(C20*Model_DB!E13),IF(C19="Cisco UCS C225 M8 All-Flash",(C20*Model_DB!E14),IF(C19="Cisco UCS C240 M4",(C20*Model_DB!E15),IF(C19="Cisco UCS C240 M5",(C20*Model_DB!E16),IF(C19="Cisco UCS C240 M6",(C20*Model_DB!E17),IF(C19="Cisco UCS C240 M6 All-Flash",(C20*Model_DB!E18),IF(C19="Cisco C240 M6 ROBO",(C20*Model_DB!E19),IF(C19="Cisco UCS S3260",(C20*Model_DB!E20),IF(C19="Cisco UCS X210c M6",(C20*Model_DB!E21),IF(C19="CX8000 Series",(C20*Model_DB!E22),IF(C19="Dell PowerEdge C6420",(C20*Model_DB!E23),IF(C19="Dell PowerEdge R640",(C20*Model_DB!E24),IF(C19="Dell PowerEdge R650",(C20*Model_DB!E25),IF(C19="Dell PowerEdge R660",(C20*Model_DB!E26),IF(C19="Dell PowerEdge R6625",(C20*Model_DB!E27),IF(C19="Dell PowerEdge R740xd",(C20*Model_DB!E28),IF(C19="Dell PowerEdge R750",(C20*Model_DB!E29),IF(C19="Dell PowerEdge R7615",(C20*Model_DB!E30),IF(C19="Dell PowerEdge R760",(C20*Model_DB!E31),IF(C19="Fujitsu Primergy RX2540 M5",(C20*Model_DB!E32),IF(C19="Fujitsu RX2540 M6",(C20*Model_DB!E33),IF(C19="Fujitsu RX2540 M7",(C20*Model_DB!E34),IF(C19="HPE Alletra Storage Server 4120",(C20*Model_DB!E35),IF(C19="HPE Apollo 4200 Gen10",(C20*Model_DB!E36),IF(C19="HPE DL320 Gen11",(C20*Model_DB!E37),IF(C19="HPE DL325 G11 All Flash",(C20*Model_DB!E38),IF(C19="HPE Apollo 4510 Gen10",(C20*Model_DB!E39),IF(C19="HPE Apollo r2200",(C20*Model_DB!E40),IF(C19="HPE ProLiant DL325 Gen11",(C20*Model_DB!E41),IF(C19="HPE ProLiant DL345 Gen11",(C20*Model_DB!E42),IF(C19="HPE ProLiant DL360 Gen10",(C20*Model_DB!E43),IF(C19="HPE ProLiant DL360 Gen10 Plus All-Flash",(C20*Model_DB!E44),IF(C19="HPE ProLiant DL380 Gen10",(C20*Model_DB!E45),IF(C19="HPE ProLiant DL380 Gen10 Plus",(C20*Model_DB!E46),IF(C19="HPE Proliant DL380 Gen11",(C20*Model_DB!E47),IF(C19="Intel M50FCP 2U R208 Platform",(C20*Model_DB!E48),IF(C19="Intel R1208WF All-Flash",(C20*Model_DB!E49),IF(C19="Intel R2208WF All-Flash",(C20*Model_DB!E50),IF(C19="Lenovo ThinkSystem SR645 All Flash",(C20*Model_DB!E51),IF(C19="Lenovo SR645 ROBO",(C20*Model_DB!E52),IF(C19="Lenovo SR650",(C20*Model_DB!E53),IF(C19="Lenovo ThinkSystem SR665 v3 All-Flash",(C20*Model_DB!E54),IF(C19="SuperMicro 6029-E1CR12L",(C20*Model_DB!E55),IF(C19="SuperMicro 1029U-TN12RV",(C20*Model_DB!E56)))))))))))))))))))))))))))))))))))))))))))))))))))))))) -> FALSE | D31: Please refer to Hardware Universe site for Cohesity hardware specifications. See https://docs.cohesity.com/hardware/Matrix/hardware-universe.htm#HardwareUniverse. For OEM's please refer to your manufacturer's documentation for hardware specifications.
A32: d. | B32: Peak Power Required (Amps@120) | C32: =SUM(ROUND(C31/120,0)) -> 0 | D32: * CX8000 Series not supported at low voltage
A33: e. | B33: Peak Power Required (Amps@220) | C33: =SUM(ROUND(C31/220,0)) -> 0 | G33: Network Cabling Recommendations
A34: f. | B34: Data Network Ports/Cables/SFPs | C34: =IF(C19="C2000 Series",(C20*Model_DB!I2),IF(C19="C3500 Series",(C20*Model_DB!I3),IF(C19="C4000 Series",(C20*Model_DB!I4),IF(C19="C5000 Series",(C20*Model_DB!I5),IF(C19="C5200 Series",(C20*Model_DB!I5),IF(C19="C6000 Series",(C20*Model_DB!I7),IF(C19="Cisco UCS C220 M5",(C20*Model_DB!I8),IF(C19="Cisco UCS 220 M5 All Flash",(C20*Model_DB!I9),IF(C19="Cisco UCS C220 M6",(C20*Model_DB!I10),IF(C19="Cisco UCS C220 M6 All Flash",(C20*Model_DB!I11),IF(C19="Cisco UCS C220 M7 All-Flash",(C20*Model_DB!I12),IF(C19="Cisco UCS C220 M6 ROBO",(C20*Model_DB!I13),IF(C19="Cisco UCS C225 M8 All-Flash",(C20*Model_DB!I14),IF(C19="Cisco UCS C240 M4",(C20*Model_DB!I15),IF(C19="Cisco UCS C240 M5",(C20*Model_DB!I16),IF(C19="Cisco UCS C240 M6",(C20*Model_DB!I17),IF(C19="Cisco UCS C240 M6 All-Flash",(C20*Model_DB!I18),IF(C19="Cisco C240 M6 ROBO",(C20*Model_DB!I19),IF(C19="Cisco UCS S3260",(C20*Model_DB!I20),IF(C19="Cisco UCS X210c M6",(C20*Model_DB!I21),IF(C19="CX8000 Series",(C20*Model_DB!I22),IF(C19="Dell PowerEdge C6420",(C20*Model_DB!I23),IF(C19="Dell PowerEdge R640",(C20*Model_DB!I24),IF(C19="Dell PowerEdge R650",(C20*Model_DB!I25),IF(C19="Dell PowerEdge R660",(C20*Model_DB!I26),IF(C19="Dell PowerEdge R6625",(C20*Model_DB!I27),IF(C19="Dell PowerEdge R740xd",(C20*Model_DB!I28),IF(C19="Dell PowerEdge R750",(C20*Model_DB!I29),IF(C19="Dell PowerEdge R7615",(C20*Model_DB!I30),IF(C19="Dell PowerEdge R760",(C20*Model_DB!I31),IF(C19="Fujitsu Primergy RX2540 M5",(C20*Model_DB!I32),IF(C19="Fujitsu RX2540 M6",(C20*Model_DB!I33),IF(C19="Fujitsu RX2540 M7",(C20*Model_DB!I34),IF(C19="HPE Alletra Storage Server 4120",(C20*Model_DB!I35),IF(C19="HPE Apollo 4200 Gen10",(C20*Model_DB!I36),IF(C19="HPE DL320 Gen11",(C20*Model_DB!I37),IF(C19="HPE DL325 G11 All Flash",(C20*Model_DB!I38),IF(C19="HPE Apollo 4510 Gen10",(C20*Model_DB!I39),IF(C19="HPE Apollo r2200",(C20*Model_DB!I40),IF(C19="HPE ProLiant DL325 Gen11",(C20*Model_DB!I41),IF(C19="HPE ProLiant DL345 Gen11",(C20*Model_DB!I42),IF(C19="HPE ProLiant DL360 Gen10",(C20*Model_DB!I43),IF(C19="HPE ProLiant DL360 Gen10 Plus All-Flash",(C20*Model_DB!I44),IF(C19="HPE ProLiant DL380 Gen10",(C20*Model_DB!I45),IF(C19="HPE ProLiant DL380 Gen10 Plus",(C20*Model_DB!I46),IF(C19="HPE Proliant DL380 Gen11",(C20*Model_DB!I47),IF(C19="Intel M50FCP 2U R208 Platform",(C20*Model_DB!I48),IF(C19="Intel R1208WF All-Flash",(C20*Model_DB!I49),IF(C19="Intel R2208WF All-Flash",(C20*Model_DB!I50),IF(C19="Lenovo ThinkSystem SR645 All Flash",(C20*Model_DB!I51),IF(C19="Lenovo SR645 ROBO",(C20*Model_DB!I52),IF(C19="Lenovo SR650",(C20*Model_DB!I53),IF(C19="Lenovo ThinkSystem SR665 v3 All-Flash",(C20*Model_DB!I54),IF(C19="SuperMicro 6029-E1CR12L",(C20*Model_DB!I55),IF(C19="SuperMicro 1029U-TN12RV",(C20*Model_DB!I56)))))))))))))))))))))))))))))))))))))))))))))))))))))))) -> FALSE | D34: = number of ports/cables/connectors needed for Physical Interface Group. | G34: * To get the best performance/redundancy, connect half of the 10GbE ports to one switch and the other half to a second switch in the same broadcast domain. Note: See Cabling tab for cabling Best Practices.
A35: g. | B35: Mgmt (IPMI) Network Port/Cables (OPTIONAL) | C35: =CONCATENATE(C20, " RJ45 (1GbE)") -> RJ45 (1GbE) | D35: Optional
A36: h. | B36: IP Address # reservations needed > > > | C36: =C20*3 -> 0 | D36: =CONCATENATE("+ ",$C$20," additional IP Addresses for each optional secondary interface.") -> + additional IP Addresses for each optional secondary interface. | E36: > > > See Network Diagram at right for more information. > > >
A37: WARNING - Confirm installation voltage compatability - See vendor specifications. For Cohesity hardware, see Cabling tab for model specifications.
A38: 4. Initial Switch / Network Settings (Primary Interface for Cluster Traffic)
A39: a. | B39: Have switch ports been allocated, configured and cabled? | D39: If not, please provide contact name and time availability of admin.
A40: b. | B40: Have the new IPs been added to all appropriate firewall rules (NTP, DNS, AD, SMTP)? | D40: IMPORTANT: See Firewall Port Requirements tab.
A41: c. | B41: Do we have internet access?
...

Sheet Cluster_Config
A1: Required Information | C1: Response | D1: Notes
A3: 1. Storage Domain Configuration (Post Install) (Usually provided by Cohesity Sales Engineer)
A4: a. | B4: Fault Tolerance (Nodes) | D4: Get from SE sizing, e.g., 1D:1N or 2D:1N (depends on # of nodes in cluster)
A5: b. | B5: Fault Tolerance: Replication Factor or Erasure Coding? | D5: RF2 is default but Verify settings with SE or Sizing document)
A6: c. | B6: RF or EC Setting? | D6: WARNING: While fault tolerance settings allow for higher than RF=2 in a 3 Node cluster, it is NOT RECOMMENDED due to the increased storage used.
A7: d. | B7: Erasure coding | D7: Inline or Post Process? | E7: Large Erasure Coding settings, e.g. 8:2 will be post-process only.
A8: e. | B8: Encryption at Storage Domain level? | D8: If not enabled at Cluster Level
A9: f. | B9: Deduplication enabled? | C9: On (Default) | D9: Inline (Default)
A10: g. | B10: Compression enabled? | C10: On (Default) | D10: Inline (Default)
A11: 2. Access Management
A12: a. | B12: Join Cluster to Active Directory Domain? | D12: A user with Active Directory Admin access is required to join the domain.
A13: b. | B13: List Active Directory Domains to join
A14: c. | B14: Enable Certificate-Based Authentication? | D14: If yes, have custom SSL certificates ready at time of installation
A15: Mapped Active Directory Principal (e.g. domain\group) | C15: Role | D15: Notes
A16: a.
A17: b.
A18: c.
A19: d.
A20: e.
A21: New Local User | C21: Role | D21: Notes
A22: a.
A23: b.
A24: c.
A25: d.
A26: Multi-Factor Authentication
A27: a. | B27: Enable Multi-Factor Authentication? | D27: Cohesity supports Authenticator TOTP or email authentication.
A28: b. | B28: Authentication Method?
A29: 3. Secondary Network Requirements - For Replication, Backup, Archive or AirGap
A30: a. | B30: Will you be adding secondary interface for replication, backup or archive? | D30: If yes, see sheet 1b-Add'l_VLANs. For AirGap, select Yes.
A31: b. | B31: Data Network Connector Type
A32: c. | B32: Interface VLAN ID (if non-native)
A33: d. | B33: Port Bonding | D33: Default is Active/Standby
A34: e. | B34: MTU Value? | D34: Default is 1500
A35: f. | B35: Custom Network Requirements?
A36: 4. Cluster Management (Helios, Saas)
A37: a. | B37: Enable Call Home/Support Bot? | D37: Enabled by default
A38: b. | B38: Helios SaaS access setting? | D38: Disabled, Administer Cluster, View Only, or Licensing Only
A39: c. | B39: Primary contact for communications with Cohesity Support? | D39: Email address.
A40: 5. Mail & Notification Settings
A41: a. | B41: System Email Address
...

Sheet Addl_VLANs
A1: This tab is required only for installations requiring additional, non-routable VLANs.
A3: 1. Additional VLAN Information
A4: Notes: For each VLAN, you will require one additional VIP per node. This sheet accommodates up to 3 additional VLANs. Copy and paste additional columns as needed. The number of VIPs listed on this sheet must match the number of nodes being installed.
B6: Node IP Information - VLAN-enabled OR multi-network interface cluster
B7: N# | C7: Node # | D7: VLAN 2 ID or Additional Interface Group | E7: VLAN 2 or Additional Interface Group VIPs | F7: VLAN 2 or Additional Interface Group Gateway / Subnet Mask / Prefix | G7: VLAN 2 or Additional Interface Group FQDN | H7: VLAN 3 or Additional Interface Group ID | I7: VLAN 3 or Additional Interface Group VIPs | J7: VLAN 3 or Additional Interface Group Gateway / Subnet Mask / Prefix | K7: VLAN 3 or Additional Interface Group FQDN | L7: VLAN 4 or Additional Interface Group | M7: VLAN 4 or Additional Interface Group VIPs | N7: VLAN 4 or Additional Interface Group Gateway / Subnet Mask / Prefix | O7: VLAN 4 or Additional Interface Group FQDN
B8: 1 | C8: =IF(B8="","",CONCATENATE("Node ",B8)) -> Node 1 | D8: Optional | E8: Optional | F8: Optional | H8: Optional | I8: Optional | J8: Optional | L8: Optional | M8: Optional | N8: Optional | O8: Optional
B9: 2 | C9: =IF(B9="","",CONCATENATE("Node ",B9)) -> Node 2 | D9: Optional | E9: Optional | F9: Optional | H9: Optional | I9: Optional | J9: Optional | L9: Optional | M9: Optional | N9: Optional | O9: Optional
B10: 3 | C10: =IF(B10="","",CONCATENATE("Node ",B10)) -> Node 3 | D10: Optional | E10: Optional | F10: Optional | H10: Optional | I10: Optional | J10: Optional | L10: Optional | M10: Optional | N10: Optional | O10: Optional
B11: 4 | C11: =IF(B11="","",CONCATENATE("Node ",B11)) -> Node 4 | D11: Optional | E11: Optional | F11: Optional | H11: Optional | I11: Optional | J11: Optional | L11: Optional | M11: Optional | N11: Optional | O11: Optional
B12: 5 | C12: =IF(B12="","",CONCATENATE("Node ",B12)) -> Node 5 | D12: Optional | E12: Optional | F12: Optional | H12: Optional | I12: Optional | J12: Optional | L12: Optional | M12: Optional
B13: 6 | C13: =IF(B13="","",CONCATENATE("Node ",B13)) -> Node 6 | D13: Optional | E13: Optional | F13: Optional | H13: Optional | I13: Optional | J13: Optional | L13: Optional | M13: Optional
B14: 7 | C14: =IF(B14="","",CONCATENATE("Node ",B14)) -> Node 7 | D14: Optional | E14: Optional | F14: Optional | H14: Optional | I14: Optional | J14: Optional | L14: Optional | M14: Optional
B15: 8 | C15: =IF(B15="","",CONCATENATE("Node ",B15)) -> Node 8 | D15: Optional | E15: Optional | F15: Optional | H15: Optional | I15: Optional | J15: Optional | L15: Optional | M15: Optional
B16: 9 | C16: =IF(B16="","",CONCATENATE("Node ",B16)) -> Node 9 | D16: Optional | E16: Optional | F16: Optional | H16: Optional | I16: Optional | J16: Optional | L16: Optional | M16: Optional
B17: 10 | C17: =IF(B17="","",CONCATENATE("Node ",B17)) -> Node 10 | D17: Optional | E17: Optional | F17: Optional | H17: Optional | I17: Optional | J17: Optional | L17: Optional | M17: Optional
B18: 11 | C18: =IF(B18="","",CONCATENATE("Node ",B18)) -> Node 11 | D18: Optional | E18: Optional | F18: Optional | H18: Optional | I18: Optional | J18: Optional | L18: Optional | M18: Optional
B19: 12 | C19: =IF(B19="","",CONCATENATE("Node ",B19)) -> Node 12 | D19: Optional | E19: Optional | F19: Optional | H19: Optional | I19: Optional | J19: Optional | L19: Optional | M19: Optional
B20: 13 | C20: =IF(B20="","",CONCATENATE("Node ",B20)) -> Node 13 | D20: Optional | E20: Optional | F20: Optional | H20: Optional | I20: Optional | J20: Optional | L20: Optional | M20: Optional
B21: 14 | C21: =IF(B21="","",CONCATENATE("Node ",B21)) -> Node 14 | D21: Optional | E21: Optional | F21: Optional | H21: Optional | I21: Optional | J21: Optional | L21: Optional | M21: Optional
B22: 15 | C22: =IF(B22="","",CONCATENATE("Node ",B22)) -> Node 15 | D22: Optional | E22: Optional | F22: Optional | H22: Optional | I22: Optional | J22: Optional | L22: Optional | M22: Optional
B23: 16 | C23: =IF(B23="","",CONCATENATE("Node ",B23)) -> Node 16 | D23: Optional | E23: Optional | F23: Optional | H23: Optional | I23: Optional | J23: Optional | L23: Optional | M23: Optional
... B31: 24 | C31: =IF(B31="","",CONCATENATE("Node ",B31)) -> Node 24 | D31: Optional | E31: Optional | F31: Optional | H31: Optional | I31: Optional | J31: Optional | L31: Optional | M31: Optional
B32: =IF(25<=PreInstall_Checklist!C20,25,"") | C32: =IF(B32="","",CONCATENATE("Node ",B32)) | D32: Optional | E32: Optional | F32: Optional | H32: Optional | I32: Optional | J32: Optional | L32: Optional | M32: Optional
B33: =IF(26<=PreInstall_Checklist!C20,26,"") | C33: =IF(B33="","",CONCATENATE("Node ",B33)) | D33: Optional | E33: Optional | F33: Optional | H33: Optional | I33: Optional | J33: Optional | L33: Optional | M33: Optional
B34: =IF(27<=PreInstall_Checklist!C20,27,"") | C34: =IF(B34="","",CONCATENATE("Node ",B34)) | D34: Optional | E34: Optional | F34: Optional | H34: Optional | I34: Optional | J34: Optional | L34: Optional | M34: Optional
B35: =IF(28<=PreInstall_Checklist!C20,28,"") | C35: =IF(B35="","",CONCATENATE("Node ",B35)) | D35: Optional | E35: Optional | F35: Optional | H35: Optional | I35: Optional | J35: Optional | L35: Optional | M35: Optional
B36: =IF(29<=PreInstall_Checklist!C20,29,"") | C36: =IF(B36="","",CONCATENATE("Node ",B36)) | D36: Optional | E36: Optional | F36: Optional | H36: Optional | I36: Optional | J36: Optional | L36: Optional | M36: Optional
B37: =IF(30<=PreInstall_Checklist!C20,30,"") | C37: =IF(B37="","",CONCATENATE("Node ",B37)) | D37: Optional | E37: Optional | F37: Optional | H37: Optional | I37: Optional | J37: Optional | L37: Optional | M37: Optional
B38: =IF(31<=PreInstall_Checklist!C20,31,"") | C38: =IF(B38="","",CONCATENATE("Node ",B38)) | D38: Optional | E38: Optional | F38: Optional | H38: Optional | I38: Optional | J38: Optional | L38: Optional | M38: Optional
B39: =IF(32<=PreInstall_Checklist!C20,32,"") | C39: =IF(B39="","",CONCATENATE("Node ",B39)) | D39: Optional | E39: Optional | F39: Optional | H39: Optional | I39: Optional | J39: Optional | L39: Optional | M39: Optional
B40: =IF(33<=PreInstall_Checklist!C20,33,"") | C40: =IF(B40="","",CONCATENATE("Node ",B40)) | D40: Optional | E40: Optional | F40: Optional | H40: Optional | I40: Optional | J40: Optional | L40: Optional | M40: Optional
B41: =IF(34<=PreInstall_Checklist!C20,34,"") | C41: =IF(B41="","",CONCATENATE("Node ",B41)) | D41: Optional | E41: Optional | F41: Optional | H41: Optional | I41: Optional | J41: Optional | L41: Optional | M41: Optional
B42: =IF(35<=PreInstall_Checklist!C20,35,"") | C42: =IF(B42="","",CONCATENATE("Node ",B42)) | D42: Optional | E42: Optional | F42: Optional | H42: Optional | I42: Optional | J42: Optional | L42: Optional | M42: Optional
B43: =IF(36<=PreInstall_Checklist!C20,36,"") | C43: =IF(B43="","",CONCATENATE("Node ",B43)) | D43: Optional | E43: Optional | F43: Optional | H43: Optional | I43: Optional | J43: Optional | L43: Optional | M43: Optional
B44: =IF(37<=PreInstall_Checklist!C20,37,"") | C44: =IF(B44="","",CONCATENATE("Node ",B44)) | D44: Optional | E44: Optional | F44: Optional | H44: Optional | I44: Optional | J44: Optional | L44: Optional | M44: Optional
B45: =IF(38<=PreInstall_Checklist!C20,38,"") | C45: =IF(B45="","",CONCATENATE("Node ",B45)) | D45: Optional | E45: Optional | F45: Optional | H45: Optional | I45: Optional | J45: Optional | L45: Optional | M45: Optional
B46: =IF(39<=PreInstall_Checklist!C20,39,"") | C46: =IF(B46="","",CONCATENATE("Node ",B46)) | D46: Optional | E46: Optional | F46: Optional | H46: Optional | I46: Optional | J46: Optional | L46: Optional | M46: Optional
B47: =IF(40<=PreInstall_Checklist!C20,40,"") | C47: =IF(B47="","",CONCATENATE("Node ",B47)) | D47: Optional | E47: Optional | F47: Optional | H47: Optional | I47: Optional | J47: Optional | L47: Optional | M47: Optional
B48: =IF(41<=PreInstall_Checklist!C20,41,"") | C48: =IF(B48="","",CONCATENATE("Node ",B48)) | D48: Optional | E48: Optional | F48: Optional | H48: Optional | I48: Optional | J48: Optional | L48: Optional | M48: Optional
B49: =IF(42<=PreInstall_Checklist!C20,42,"") | C49: =IF(B49="","",CONCATENATE("Node ",B49)) | D49: Optional | E49: Optional | F49: Optional | H49: Optional | I49: Optional | J49: Optional | L49: Optional | M49: Optional
...

Sheet Completion_Form
A1: Please complete and sign this form and return to your Installation Engineer.
A2: Post-Installation Checklist v15.3
A3: This checklist is used to sign-off on the installation of a Cohesity cluster. This form can be completed electronically, digitally signed and returned via email to your project coordinator. Click the check boxes below as applicable to indicate completion of the task noted.
A4: Done | B4: Declined | C4: Follow up | D4: Sales Order #: | F4: Cluster ID #:
D5: Customer Name: | F5: Installation Address:
D6: Installation Date:
D7: Cohesity Node Installation
D8: Installed and cabled Cohesity nodes (Cohesity Hardware ONLY)
D9: Cluster nodes configured with desired target version of Cohesity software
D10: Latest software patches/fixes applied
D11: Cohesity Cluster Creation
D12: Applied custom Cohesity node network settings
D13: Created Cohesity cluster using the information provided on the PreInstall_Checklist
D14: Cohesity Helios Configuration
D15: Integrated the Cohesity cluster with the customer infrastructure per settings completed on Cluster_Config tab
D16: Configured the Storage Domain settings (Cluster resiliency, data reduction settings, quotas, etc.)
D17: Configured the Cluster Network settings (VLANs, MTU, etc.)
... D25: Resolved any outstanding cluster alerts and configured notification rules
D26: Security Hardening Best Practices > > > > see > > | E26: Cohesity Platform Security Hardening Guide Best Practices
D27: MANDATORY: Installation Engineers - review and assist with the following items: | G27: docs.cohesity.com OS
D28: Security Feature | E28: Menu Path | G28: 7 | H28: 7.1.2 | I28: 7.2.2
D29: Changed 'admin/local user' password | E29: Settings > Access Management | G29: 7 | H29: 7.1.2 | I29: 7.2.2
D30: Changed 'support user' password | E30: Settings > Access Management > Support tab | G30: 7 | H30: 7.1.2 | I30: 7.2.2
D31: Changed 'cohesity_console' password | E31: (CLI ONLY) | G31: 7 | H31: 7.1.2 | I31: 7.2.2
D32: Changed IPMI password | E32: Settings > Networking > IPMI tab - Setup IPMI | G32: 7 | H32: 7.1.2 | I32: 7.2.2
D33: Enabled MFA for local users | E33: Settings > Access Mgmt > MFA tab | G33: 7 | H33: 7.1.2 | I33: 7.2.2
D34: Enabled MFA for the Support User Account | E34: Settings > Access Mgmt > Support | G34: 7 | H34: 7.1.2 | I34: 7.2.2
D35: Assigned least privilege roles | E35: Settings > Access Mgmt > Roles | G35: 7 | H35: 7.1.2 | I35: 7.2.2
D36: Configured Quorums | E36: Security > Quorum (Helios ONLY) | G36: 7 | H36: 7.1.2 | I36: 7.2.2
D37: Updated SSL Certificates (w/ custom CSRs) | E37: (CLI ONLY) | G37: 7 | H37: 7.1.2 | I37: 7.2.2
D38: Enabled DataLock | E38: System > Access Mgmt > Add Local Users, Data Protection > Policies | G38: 7 | H38: 7.1.2 | I38: 7.2.2
D39: Enabled NTP Authentication | E39: Settings > Cluster Settings> Use Authentication Key toggle | G39: 7 | H39: 7.1.2 | I39: 7.2.2
D40: Enabled node-to-node encryption | E40: (CLI ONLY) | G40: 7 | H40: 7.1.2 | I40: 7.2.2
D41: Enabled cluster level encryption | E41: Settings > Summary tab
D42: Enabled audit logs | E42: System > Audit Logs > Log Settings > File Services/Log Settings | G42: 7 | H42: 7.1.2 | I42: 7.2.2
D43: Enabled SSO * | E43: Settings > Access Mgmt > SSO tab | G43: 7 | H43: 7.1.2 | I43: 7.2.2
D45: Installation TOI & Closeout
D46: Cohesity GUI Overview
D47: Cohesity Support Overview and MyCohesity Account creation
D48: Explained Cohesity Remote Support Channel abilities
...

Sheet Networking Examples
A1: Networking Examples
B3: IP Networking Example
B31: Network Bonding Example
F60: Bond /Port Options
B61: Per Port Settings
B62: Note: The data paths above are actually made up of 2 links per node to maintain network redundancy.
B63: Cohesity supports two types of bonding. The default configuration requires no special switch settings
B65: Option 1: No Switch Port Aggregation (Default) | H65: Switch A | K65: Switch B
C66: * Node Bond: Active-Backup (Bond Mode 1)
C67: * Switch Port Aggregation: N/A
C68: * Connectivity:
D69: Node Port 1 -> Switch A
D70: Node Port 2 -> Switch B
H72: Port 1 | I72: Port 2
B73: Option 2: Use Switch Port Aggregation (LACP)
C74: * Node Bond: 802.3ad (Bond Mode 4)
C75: * Switch Port Aggregation: LACP (802.3ad)
C76: * Connectivity:
D77: Follow your switch settings / best practices
F80: MTU Settings
B81: * The default setting for a interfaces is 1500 MTU.
B82: * We strongly urge you to keep these defaults unless your company standardizes on jumbo frames.
B83: * If you wish to use jumbo frames, you should set the same MTU from end to end (interfaces and switches).
B84: - Failure to do so, will result in poor network performance or loss of connectivity.
F86: Multicast Settings
C106: Typical Network Topologies for Cluster Partition/Node Traffic
F107: (Excluding any IPMI Connectivity/Traffic)
C108: Scenario 1: Flat Networks (No VLANs)
C135: Scenario 2: Single, Untagged/Native VLAN
C163: Scenario 3: Single, Tagged Network
C190: Scenario 4: Multiple, Tagged Network

Sheet Firewalls
A1: Manage Firewall Ports (7.2.2)
A2: You must open certain ports in the firewall to allow the Cohesity Cluster to transmit and receive data. You can isolate traffic on physical or logical networks to improve performance and security. The Cluster sends the following types of traffic over the network: • IPMI traffic for admins to access Nodes, typically for pre-boot BIOS access and post-boot console access. • Management traffic: - from Nodes to external services such as Active Directory, DNS, NTP and SNMP - for admins to access the Cohesity Cluster • Backup and restore traffic for moving data between protected Sources and the Cluster. • Replication traffic for replicating data from one Cluster to another Cluster. • Data access (NAS) traffic for accessing data on the Cluster by using protocols such as NFS, SMB or S3. • Archive and tiering traffic for moving data to external targets such as a cloud or tape system. • Support Channel traffic between Nodes and the Cohesity Support servers. • Internal traffic between Nodes in a Cluster. The following diagram shows the port requirements and directional flow for some of the traffic in a typical Cluster. More information is provided following the diagram.
B5: Using the Cohesity Dashboard or CLI, you can configure application-based firewall rules and manage incoming traffic on a Cohesity cluster. For more details, see Manage Application-Based Firewall Rules.
A6: Identify Source IP of Outgoing Traffic
A7: The source IP of outgoing traffic depends on the matching static route’s outgoing interface. If there is no static route, the source IP depends on the default route's outgoing interface. Use the route list command to view the list of routes configured on an interface in a Cohesity cluster and the IP address of the destination network.
A8: In the following example, the route list command output shows the VLAN interface (intf_group1.100) of a cluster configured with the default route.
B9: iris_cli route list
B10: DEST NETWORK : 0.0.0.0/0
B11: NEXT HOP : 10.1.100.1
B12: INTERFACE GROUP NAME : intf_group1.100
B13: For more details, see Add a Static Route.
A16: Cluster Management
A17: Cluster Upgrade
A18: NOTE: | B18: If the Cohesity cluster uses an interface with the node IP address to reach the external server or client, configure the firewall settings to allow the node IP addresses. If the Cohesity cluster uses an interface with only virtual IP addresses, configure the firewall settings to allow the virtual IP addresses. To identify whether the source IP is Static IP or Virtual IP for outgoing traffic, see Identify Source IP of Outgoing Traffic.
A21: Outgoing Traffic
B22: Source | C22: Destination | D22: Destination Port | E22: Protocol | F22: Usage Notes
B23: Cohesity cluster | C23: http://downloads.cohesity.com/oauth2/login | D23: 443 | E23: TCP | F23: For cluster upgrade packages. You can select and download the version packages from downloads.cohesity.com, AWS location, or Cloudfront site. The cluster upgrade packages are hosted on the Amazon S3 CloudFront server to increase the download speed of release packages.
C25: http://s3-us-west-2.amazonaws.com
C27: Amazon CloudFront CDN (Content Delivery Network) Facility: http://dipowd173xxgy.cloudfront.net/
A32: Agent Upgrade
A33: Incoming Traffic
B34: Source | C34: Destination | D34: Destination Port | E34: Protocol | F34: Usage Notes
B35: Client | C35: Cohesity cluster | D35: 80443 | E35: TCP | F35: For Agent upgrade from UI.
A37: Troubleshooting
A39: Incoming Traffic
B40: Source | C40: Destination | D40: Destination Port | E40: Protocol | F40: Usage Notes
B41: SSH client | C41: Cohesity cluster | D41: 22 | E41: TCP | F41: Support Channel used by Cohesity Support for troubleshooting
A42: Networking
A43: Agent Communication
A44: Outgoing Traffic
B45: Source | C45: Destination | D45: Destination Port | E45: Protocol | F45: Usage Notes | G45: Type of Traffic
B46: Cohesity cluster | C46: Cohesity Agent | D46: 50051* | E46: TCP | F46: Used for Cohesity Agent and Agent less data transfer to the cluster. Needs to be open on all nodes on the cluster and any backup target using the Cohesity Agent, such as SQL servers, physical servers and VMs running the Cohesity installed Agent. Cohesity clusters pick any available ephemeral port to initiate communication with the agent service via port 50051. The firewall needs to allow the connection request from the Cohesity nodes if the destination port is 50051. | G46: Backup and Recovery
F47: Cohesity clusters pick any available ephemeral port to initiate communication with the agent service via port 50051. The firewall needs to allow the connection request from the Cohesity nodes if the destination port is 50051.
A49: Network Services
A51: Incoming Traffic
B53: Source | C53: Destination | D53: Destination Port | E53: Protocol | F53: Usage Notes | G53: Type of Traffic
B54: Cohesity cluster | C54: DNS | D54: 53 | E54: TCP/UDP | F54: DNS, if an external DNS server is configured. | G54: Management
B55: Cohesity cluster | C55: DNS server | D55: 5353 | E55: UDP | F55: mDNS multicasting.
A57: Outgoing Traffic
B59: Source | C59: Destination | D59: Destination Port | E59: Protocol | F59: Usage Notes | G59: Type of Traffic
...

Sheet Model_DB
B1: Model_Num | C1: Nodes / Block | D1: Block RU | E1: Peak watts per node | F1: Power Cables/blk | G1: Node 40Gb | H1: Node 25Gb | I1: Node 10Gb | J1: Node 1Gb | K1: Node IPMI | L1: 100Gb | M1: 16G/32G FC PCIe | N1: Connector Type | Q1: ServerType | R1: OracleType | S1: SQLVersion | T1: vCenterVersion | U1: NetAppLIF | V1: FileLevelBackup | W1: Other | X1: DiskType | AD1: Methodology | AE1: HyperPolicy | AF1: AgentPolicy | AG1: NativePolicy | AH1: HyperProtection | AI1: AgentProtection | AJ1: Native Protection | AK1: HyperScheduling | AL1: AgentScheduling | AM1: NativeScheduling
A2: EOL | B2: C2000 Series | C2: 4 | D2: 2 | E2: 1200 | F2: 2 | I2: 2 | J2: 2 | K2: 1 | Q2: Oracle | R2: Oracle 11gR2 | S2: SQL Server 2008 | T2: vCenter Version 5.5 | U2: NetApp Private LIF | V2: Unix | W2: Other | X2: Physical | AD2: Hypervisor | AE2: by Classification (Prod/Dev/Test) | AF2: by Classification (Prod/Dev/Test) | AG2: not applicable | AH2: by Classification (Prod/Dev/Test) | AI2: by Classification (Prod/Dev/Test) | AJ2: not applicable | AK2: Daily | AL2: Daily | AM2: not applicable
A3: EOL | B3: C3500 Series | C3: 1 | D3: 2 | E3: 900 | F3: 2 | I3: 2 | J3: 2 | K3: 1 | Q3: SQL | R3: Oracle 12cR1 | S3: SQL Server 2008 R2 | T3: vCenter Version 6.0 | U3: NetApp Public LIF | V3: AIX | W3: N/A | X3: Virtual | AD3: Agent-Based | AE3: by Application | AF3: by Application | AH3: by Service Level | AI3: by Service Level | AK3: Weekly | AL3: Weekly
A4: EOS | B4: C4000 Series | C4: 4 | D4: 2 | E4: 900 | F4: 2 | I4: 2 | K4: 1 | Q4: vCenter | R4: Oracle 12cR2 | S4: SQL Server 2012 | T4: vCenter Version 6.5 | V4: Solaris | X4: Both | AD4: Native SQL using SMB | AE4: by Department | AF4: by Department | AK4: Monthly | AL4: Monthly
B5: C5000 Series | C5: 4 | D5: 2 | E5: 423 | F5: 2 | G5: 2 | H5: 2 | I5: 2 | K5: 1 | L5: 2 | M5: 2 | Q5: ESX | R5: Oracle 18c | S5: SQL Server 2014 | T5: vCenter Version 6.7 | V5: Windows | AE5: by Service Level | AF5: by Service Level | AK5: Yearly | AL5: Yearly
B6: C5200 Series | C6: 4 | D6: 2 | E6: 1690 | F6: 2 | H6: 2 | I6: 2 | K6: 1 | Q6: NetApp | S6: SQL Server 2016 | AK6: by Outage Window | AL6: by Outage Window
B7: C6000 Series | C7: 1 | D7: 1 | E7: 650 | F7: 2 | G7: 2 | H7: 2 | I7: 2 | K7: 1 | Q7: Isilon | S7: SQL Server 2017 | AK7: by Classification | AL7: by Classification
B8: Cisco UCS C220 M5 | C8: 1 | D8: 1 | E8: 770 | F8: 2 | H8: 2 | I8: 2 | K8: 1 | Q8: FileLevelBackup
B9: Cisco UCS 220 M5 All Flash | C9: 1 | D9: 1 | E9: 1600 | F9: 2 | H9: 4 | I9: 2 | Q9: Other
B10: Cisco UCS C220 M6 | C10: 1 | D10: 2 | E10: 1050 | F10: 2 | H10: 4 | I10: 4 | K10: 1
B11: Cisco UCS C220 M6 All Flash | C11: 1 | D11: 1 | E11: 1200 | F11: 2 | I11: 2
B12: Cisco UCS C220 M7 All-Flash | C12: 1 | D12: 1 | E12: 1600 | F12: 2 | I12: 2
B13: Cisco UCS C220 M6 ROBO | C13: 1 | D13: 1 | E13: 2300 | F13: 2 | G13: 2 | I13: 2 | N13: UCS VIC 1467-MLOM | Q13: Method | R13: Replication_Factor | S13: Erasure_Coding
B14: Cisco UCS C225 M8 All-Flash | C14: 1 | D14: 1 | E14: 2300 | F14: 2 | I14: 2 | Q14: Replication_Factor | R14: RF2 | S14: "2:1"
B15: Cisco UCS C240 M4 | C15: 1 | D15: 2 | E15: 1200 | F15: 2 | I15: 2 | J15: 2 | K15: 1 | Q15: Erasure_Coding | R15: RF3 | S15: "2:2"
B16: Cisco UCS C240 M5 | C16: 1 | D16: 2 | E16: 800 | F16: 2 | I16: 2 | J16: 2 | K16: 1 | R16: RF4 | S16: "2:3"
B17: Cisco UCS C240 M6 | C17: 1 | D17: 2 | E17: 800 | F17: 2 | H17: 4 | I17: 4 | J17: 2 | K17: 1 | S17: "3:1"
B18: Cisco UCS C240 M6 All-Flash | C18: 1 | D18: 2 | E18: 2300 | F18: 2 | I18: 2 | S18: "3:2"
B19: Cisco C240 M6 ROBO | C19: 1 | D19: 1 | E19: 800 | F19: 2 | I19: 2 | J19: 1 | K19: 1 | S19: "3:3"
B20: Cisco UCS S3260 | C20: 1 | D20: 4 | E20: 1000 | F20: 4 | I20: 2 | J20: 2 | K20: 1 | S20: "4:1"
B21: Cisco UCS X210c M6 | C21: 1 | D21: 1 | E21: 1300 | F21: 2 | H21: 2 | I21: 2 | N21: UCS VIC 14425 | S21: "4:2"
B22: CX8000 Series | C22: 4 | D22: 2 | E22: 525 | F22: 2 | I22: 2 | K22: 1 | S22: "4:3"
B23: Dell PowerEdge C6420 | C23: 4 | D23: 2 | E23: 600 | F23: 2 | G23: 2 | H23: 2 | I23: 2 | K23: 1 | N23: SFP+ | S23: "5:1"
B24: Dell PowerEdge R640 | C24: 1 | D24: 1 | E24: 750 | F24: 2 | I24: 2 | K24: 1 | N24: SFP+ | S24: "5:2"
B25: Dell PowerEdge R650 | C25: 1 | D25: 1 | E25: 1400 | F25: 2 | I25: 4 | S25: "5:3"
B26: Dell PowerEdge R660 | C26: 1 | D26: 1 | E26: 1800 | F26: 2 | H26: 4 | I26: 4 | S26: "6:2"
B27: Dell PowerEdge R6625 | C27: 1 | D27: 1 | E27: 1400 | F27: 2 | H27: 4 | I27: 4 | J27: 2 | M27: 2 | S27: "8:2"
B28: Dell PowerEdge R740xd | C28: 1 | D28: 2 | E28: 1100 | F28: 2 | I28: 2 | J28: 2 | K28: 1 | N28: SFP+
B29: Dell PowerEdge R750 | C29: 1 | D29: 2 | E29: 2400 | F29: 2 | I29: 4 | J29: 4
B30: Dell PowerEdge R7615 | C30: 1 | D30: 2 | E30: 1400 | F30: 2 | H30: 2 | I30: 2 | J30: 2
B31: Dell PowerEdge R760 | C31: 1 | D31: 2 | E31: 2800 | F31: 2 | H31: 4 | I31: 4
B32: Fujitsu Primergy RX2540 M5 | C32: 1 | D32: 2 | E32: 715 | F32: 2 | I32: 2
B33: Fujitsu RX2540 M6 | C33: 1 | D33: 2 | E33: 1600 | F33: 2 | H33: 2 | I33: 4
B34: Fujitsu RX2540 M7 | C34: 1 | D34: 2 | E34: 1800 | F34: 2 | I34: 2
B35: HPE Alletra Storage Server 4120 | C35: 1 | D35: 2 | E35: 2200 | F35: 2 | I35: 2 | L35: 2 | M35: 2 | N35: Base-T, SFP28, QSFP28 | Q35: Failures Tolerated (Node Failures) | R35: Fault Tolerance (Disk: Node Failures) | S35: Max RF Levels Available (If EC not used) | T35: Max EC Levels Available (If RF not used) | U35: Min # | V35: Recommended #
B36: HPE Apollo 4200 Gen10 | C36: 1 | D36: 2 | E36: 1600 | F36: 2 | H36: 2 | I36: 2 | J36: 2 | K36: 1 | L36: 2 | M36: 2 | N36: SFP+ or RJ-45 | U36: of Nodes | V36: of Nodes (Min + Additional Nodes for healing)
A37: EOL | B37: HPE Apollo 4510 Gen10 | C37: 1 | D37: 4 | E37: 1600 | F37: 4 | I37: 2 | J37: 2 | K37: 1 | T37: 0.084027778 | U37: 3 | V37: 3+1
A38: EOL | B38: HPE Apollo r2200 | C38: 4 | D38: 2 | E38: 1600 | F38: 2 | I38: 2 | J38: 2 | K38: 1 | T38: 0.12569444 | U38: 4 | V38: 4+1
B39: HPE DL320 Gen11 | C39: 1 | D39: 1 | E39: 1600 | F39: 2 | H39: 4 | I39: 2 | L39: 2 | T39: 0.16736111 | U39: 5 | V39: 5+1
B40: HPE DL325 G11 All Flash | C40: 1 | D40: 1 | E40: 1600 | F40: 2 | H40: 2 | I40: 2 | N40: Dual port 10Gb BASE-T Dual port 10/25Gb SFP28 | R40: 1D:1N | S40: 2 | T40: 0.20902778 | U40: 6 | V40: 6+1
...

Sheet Cabling
A1: Cabling a Cohesity Cluster
A2: IMPORTANT: Cabling instructions vary significantly depending on the hardware type, connectors and available network connections. For a complete listing of hardware setup guides that include cabling instructions, please visit the following URL and select the Hardware Model > Model # Setup Guide
A3: https://docs.cohesity.com/Setup/Welcome/InitialClusterSetup.htm
A4: The Images below are for representation purposes only. Port layout and appearance will vary depending on the hardware model.
A6: EXAMPLE: Cable C5000 Series with SFP+ 10 GbE Network Connections (PCIe Slot)
A7: The following figure of the Cohesity cluster back panel shows how to cable SFP+ 10GbE network connections in the PCIe slot. See the instructions on how to cable the Cohesity cluster after the figure below. C5000 Series (NIC Type: SFP+; Slot: PCIe Slot)
A8: When you receive your Cohesity C5000 Series appliance, you will find the SFP+ NICs installed in the PCIe slot. When you set up your appliance, you will use ports P1 and P2 to create bond0. The following table enumerates the port numbering on the NIC cards.
A11: To cable the Cohesity cluster: 1. Connect four network cables to the 10GbE ports of a single switch. Connect the other ends of the four network cables to the left 10GbE ports of the Cohesity cluster as shown in the figure above. Note that you can substitute a Fiber Optic SFP+ cable for the coaxial cable. 2. Connect four network cables to the 10GbE ports of a different switch as shown in the figure above. Connect the other ends of the four network cables to the right 10GbE ports of the Cohesity cluster. 3. Connect the four blue Cat 6 network cables to 1GbE ports in a switch as shown in the figure above. Connect the other ends of the cables to the IPMI 1GbE ports in the Cohesity cluster. 4. Connect the power cables to two different power sources.
A12: Note: Cohesity does not recommend having a Cohesity cluster with a mixture of nodes with SFP+ 10GbE ports and nodes with RJ45 10GbE ports. This is currently an untested configuration.
A14: C5000 Series System Specifications
A33: C6000 Series System Specifications
A54: CX8000 Series System Specifications

Sheet DNS Config
A1: DNS Configuration
A2: This section describes how to set up DNS.
A3: To load-share traffic among nodes in a Cohesity Cluster, the resolving DNS server for the nodes round-robins resolution among the VIPs of the Cohesity Cluster.
A4: Configuring Round Robin DNS in a Windows Environment
A5: The Microsoft Windows DNS Server supports round robin. This feature configures DNS to send both IP addresses when a query is received for myserver.mydomain.com. The client (or Resolver) always uses the first address. The next DNS query for the same name returns returns an IP address in the order of the list of IP addresses.
A6: To configure round-robin DNS in a Windows environment, create a DNS A record for each VIP associated with the hostname of the Cohesity Cluster.
A7: 1. Click Start, click Administrative Tools, and then click DNS.
A8: 2. In DNS Manager, click the DNS server that manages your records.
A9: 3. Click Forward Lookup Zones to expand the list.
A10: 4. Right-click the DNS domain that you need to add records to, and then click New Host (A or AAAA).
A11: 5. In the IP Address box, type the IP address of one the VIPs and then select Create associated pointer (PTR) record or Allow any authenticated user to update DNS records with the same owner name, if applicable.
A12: 6. Continue creating records for each VIP that will participate in DNS load balancing.
... A29: As a test, you can perform an NSLOOKUP to confirm that DNS is returning all IPs associated with the name.

Sheet Check_NTP
A1: Check NTP
A2: Creating a Cohesity cluster requires that NTP and DNS services are functioning and reachable from the network where the cluster will be located. This should be verified this as part of the installation worksheet.
B4: To check NTP using a Mac host use the following command:
B5: sntp <ntp server IP or FQDN>
B6: A successful test will return output similar to the following screenshot:
B12: To check NTP using a Windows host use the following command:
B13: w32tm /stripchart /computer:<ntp server IP or FQDN>
B14: A successful test will return output similar to the following screenshot:
B21: To check NTP using a Linux host (Centos in this example) use the following command:
B22: ntpdate -d <ntp server IP or FQDN>
B23: A successful test will return output similar to the following screenshot:

Sheet EC Settings
A1: EC Settings
A2: Summary guidance. Green = optimal
A3: Fault Tolerance | B3: Storage Domain EC | C3: Default EC Processing Method
C4: <=6.5.1c | D4: 6.5.1d and Later
A5: 1D:1N | B5: EC 2:1 | C5: Inline | D5: Inline
B6: EC 3:1 | C6: Inline | D6: Inline
B7: EC 4:1 | C7: Post Process | D7: Inline
B8: EC 5:1 | C8: Post Process | D8: Post Process
A9: 2D:1N | B9: EC 2:2 | C9: Inline | D9: Inline
B10: EC 3:2 | C10: Inline | D10: Inline
B11: EC 4:2 | C11: Post Process | D11: Inline
B12: EC 5:2 | C12: Post Process | D12: Post Process
B13: EC 6:2 | C13: Post-Process-Only | D13: Post-Process-Only
B14: EC 8:2 | C14: Post-Process-Only | D14: Post-Process-Only
A15: 2D:2N | B15: EC 2:2 | C15: Inline | D15: Inline
B16: EC 3:2 | C16: Inline | D16: Inline
B17: EC 4:2 | C17: Post Process | D17: Inline
B18: EC 5:2 | C18: Post Process | D18: Post Process
B19: EC 6:2 | C19: Post-Process-Only | D19: Post-Process-Only
B20: EC 8:2 | C20: Post-Process-Only | D20: Post-Process-Only
A21: 3D:1N | B21: EC 3:3 | C21: Inline | D21: Inline
B22: EC 4:3 | C22: Post Process | D22: Post Process
B23: EC 5:3 | C23: Post Process | D23: Post Process
A24: 3D:2N | B24: EC 3:3 | C24: Inline | D24: Inline
B25: EC 4:3 | C25: Post Process | D25: Post Process
B26: EC 5:3 | C26: Post Process | D26: Post Process
A27: For more details, refer to this EPIC ENG-173081 Inline EC improvements.

Sheet 2 - Cloud Edition
A1: Required Information | C1: Response | D1: Notes
A2: 1. Cloud Edition
A3: a. | B3: Cloud Provider | D3: AWS, Azure, Google
A4: b. | B4: Name of contact – company cloud administrator?
A5: c. | B5: Do you have a single subscription or multiple subscriptions?
A6: d. | B6: Do you have a VPN Tunnel or Express Route to the subscription?
A7: e. | B7: Are your firewall ports open on network resource group within the cloud description?
A8: f. | B8: Have you completed the required cloud provider information needed to setup CloudEdition?
A9: g. | B9: Does the account have enough privileges to access all resources? E.g. superuser?
A10: h. | B10: Do you have a control VM in place?
A11: i. | B11: Azure - Government customer? If yes, DoD GCC High? | D11: See release notes for product version compatabilities.
A12: j. | B12: Do you know what node size you will need to use?
A13: k. | B13: Cohesity OS version?
A14: l. | B14: Project ID
A15: m. | B15: Region
A16: n. | B16: Zone
A17: o. | B17: VPC
A18: p. | B18: Subnet
A19: q. | B19: VPC Connector
A20: r. | B20: Network Tab
A21: s. | B21: Label
B23: * Questions should be answered by the Customer Cloud Adminstrator

Sheet 2a-AWS
A1: Required Information | B1: Response | C1: Notes
A2: 1. AWS Platform Specific
A3: AWS Account Number
A4: AWS Region
A5: Node Size | C5: S/M/L/XL - For XL Cloud tier will be enabled
A6: AWS IAM Policy | C6: Check the Setup Guide for details
A7: AWS IAM User
A8: Access Key
A9: Secret Access Key
A10: Region
A11: AWS VPC and Subnet
A12: Security Group
A13: Limit for Nodes is increased (minimum 3) | C13: Default for m4.4xlarge is 0, increase that the total number of nodes which are being deployed.
A14: Cluster Name
A15: Number of Nodes
A16: DNS Server
A17: NTP Server
A18: Domain Name
A19: Cluster Encryption
A20: AWS Account ID
A21: Your Company Name
A22: Email Address
A23: AWS Instance Type
A24: AWS Availability Zone
A25: Cohesity Software Version
A26: Control Instance AMI ID | C26: For Manual Installs only
A27: Control Instance Password | C27: For Manual Installs Only
A28: Cohesity Cluster Instance AMI ID | C28: For Manual Installs OnlY
A29: Limits and Quotas are Increased? | C29: Because of Certified Instance Type
A30: Is Security Group Defined?
A31: Subscription of Centos Image in Marketplace?
A32: Your Name
A33: 2. Cloud Specific - AWS
A34: aws_credentials_access_key_id | C34: customer_value
A35: aws_credentials_secret_access_key | C35: customer_value
A36: cohesity_aws_region | C36: us-east-1
A37: cohesity_aws_zone | C37: us-east-1b
A38: cohesity_aws_cluster_name | C38: Cluster Name
A39: cohesity_aws_num_vms | C39: 3
A40: cohesity_aws__vm_ip_addresses | C40: 10.200.0.202,10.200.0.203,10.200.0.204
...

Sheet 2b-Azure
A1: PARAMETER | B1: CUSTOMER VALUE | C1: EXAMPLE/NOTES
A2: 1. Azure Platform Specific
A3: Azure Account Number | C3: This property lets you reuse an existing VHD file, to reduce the amount it takes to create the new cluster. Specify the storage account that contains the SSD you want to use, such as chsty449608976083ssd00. Otherwise, specify two quotes "" (with nothing between them).
A4: Azure Region | C4: If using XL Nodes, create an account in the same Azure Region.
A5: Azure AD
A6: AD App Registration | C6: Completed (Yes / No)
A7: Custom Role Creation | C7: Completed (Yes / No)
A8: Assignment of Application to a Role
A9: Azure Subscription ID
A10: Application ID
A11: Application Key
A12: Tenant ID
A13: Region
A14: Compute Resource Group
A15: Storage Resource Group
A16: Virtual Network
A17: Cluster Name
A18: Node Size | C18: Small/Medium/Large
A19: XL Nodes | C19: Yes/NO - If Yes, Create an account in the same Azure Region
A20: Number of Nodes | C20: Internet Connectivity from VPC
A21: Fault Tolerance | C21: Because of Certified Instance Type
A22: DNS Servers
A23: NTP Servers
A24: Domain Name
A25: Cluster Encryption
A26: Your Name
A27: Your Company Name
A28: Email Address
A29: Azure Instance Type
A30: 2. Cloud Specific - Azure
A31: azure_application_id | C31: "xxxxxxxx-xxxx-xxxx-xxxx-xxxxxxxxxxxx", e.g., a6f80f7xxxxxxxxxxxxxxx1a0a67
A32: azure_application_key | C32: "xxxxxxxx-xxxx-xxxx-xxxx-xxxxxxxxxxxx", e.g., 35yhxxxxxxxxxxxxxxxWWK+
A33: azure_tenant_id | C33: "xxxxxxxx-xxxx-xxxx-xxxx-xxxxxxxxxxxx", e.g., a9a464a9xxxxxxxxxxxxxxx23ef
A34: azure_subscription_id | C34: "xxxxxxxx-xxxx-xxxx-xxxx-xxxxxxxxxxxx", f371xxxxxxxxxxxxxxx716
A35: azure_is_subscription_us_gov_cloud | C35: FALSE / TRUE (.gov)
A36: cohesity_azure_cluster_resource_group_name | C36: "AZCohesity"
A37: cohesity_azure_cluster_storage_account_prefix | C37: "azcoh"
A38: cohesity_azure_virtual_network_resource_group_name | C38: "resource_group_name", e.g., CE-Control-EastUS
A39: cohesity_azure_virtual_network_name | C39: "virtual_network_name", e.g., CE-Control-EastUS-vnet
A40: cohesity_azure_virtual_network_subnet_name | C40: e.g., "CommonServicesSN",
...

Sheet 2c-GCP
A1: Required Information | B1: Response | C1: Notes
A2: 1. GCP Platform Specific
A3: Project ID
A4: Region
A5: GCP Zone
A6: VPC
A7: Subnet
A8: VPC Connector
A9: Network Tab
A10: Label
A11: Cluster Name
A12: Cluster Image
A13: Node Size | C13: S/M/L and NextGen
A14: Number of Nodes
A15: Fault Tolerance
A16: DNS Servers
A17: NTP Servers
A18: Domain Names
A19: Cluster Encryption
A20: Project Name
A21: GCP Image Name
A22: Control VM Password
A23: Your Company Name
A24: Email Address
A25: Cohesity Software Version
... A27: 2. Cloud Specific - GCP
A28: gcp_authentication_filepath | C28: The full directory path to your GCP service account key file on the Control VM, for example: /home/cohesity/software/key/Cohesity<uniqueNumber>.json For more information, see Create and Copy a GCP Service Account Key.
A29: cohesity_cluster_name | C29: The name of the Cohesity cluster.
A30: cohesity_gcp_cluster_size | C30: The capacity of the Cohesity cluster:small - 2TB HDD and 1.6TB SSD per node.medium - 6TB HDD and 1.6TB SSD per node.large - 12TB HDD and 1.6TB SSD per node.Next-gen - 2TB HDD and 1.6 TB SSD per node For more information, see Verify Resource Quotas
A31: gcp_num_vms | C31: Number of VMs.
A32: gcp_vm_ip_addresses | C32: Enter the IP Addresses for the number of VMs.
A33: gcp_src_image_name | C33: The name of the Cohesity custom operating system source image provided by Cohesity and available from Google Cloud Platform.
A34: gcp_src_image_project_id | C34: The Project ID of the Cohesity GCP source project that contains the custom images used to create the Control VM and node VMs that make up the Cohesity cluster. Example: cloudedition- exports (it does not typically contain any spaces)
A35: gcp_vpc_network_name | C35: The name of the Virtual Private Cloud (VPC) network to provide connectivity to the GCP instances (nodes) of the Cohesity cluster.
